Internal Server Error: /editinvoice/368/
Traceback (most recent call last):
  File "C:\New folder\Lickees\venv\Lib\site-packages\django\core\handlers\exception.py", line 55, in inner
    response = get_response(request)
  File "C:\New folder\Lickees\venv\Lib\site-packages\django\core\handlers\base.py", line 197, in _get_response
    response = wrapped_callback(request, *callback_args, **callback_kwargs)
  File "C:\New folder\Lickees\BillingSoftware\app\views.py", line 497, in edit_invoice
    locations = customer.objects.all()
                ^^^^^^^^
UnboundLocalError: cannot access local variable 'customer' where it is not associated with a value
"POST /editinvoice/368/ HTTP/1.1" 500 145
Internal Server Error: /delete_customer/1/
Traceback (most recent call last):
  File "C:\New folder\Lickees\venv\Lib\site-packages\django\core\handlers\exception.py", line 55, in inner
    response = get_response(request)
  File "C:\New folder\Lickees\venv\Lib\site-packages\django\core\handlers\base.py", line 197, in _get_response
    response = wrapped_callback(request, *callback_args, **callback_kwargs)
  File "C:\New folder\Lickees\BillingSoftware\app\views.py", line 872, in delete_customer
    return redirect('customer_list')
  File "C:\New folder\Lickees\venv\Lib\site-packages\django\shortcuts.py", line 49, in redirect
    return redirect_class(resolve_url(to, *args, **kwargs))
                          ~~~~~~~~~~~^^^^^^^^^^^^^^^^^^^^^
  File "C:\New folder\Lickees\venv\Lib\site-packages\django\shortcuts.py", line 180, in resolve_url
    return reverse(to, args=args, kwargs=kwargs)
  File "C:\New folder\Lickees\venv\Lib\site-packages\django\urls\base.py", line 88, in reverse
    return resolver._reverse_with_prefix(view, prefix, *args, **kwargs)
           ~~~~~~~~~~~~~~~~~~~~~~~~~~~~~^^^^^^^^^^^^^^^^^^^^^^^^^^^^^^^
  File "C:\New folder\Lickees\venv\Lib\site-packages\django\urls\resolvers.py", line 831, in _reverse_with_prefix
    raise NoReverseMatch(msg)
django.urls.exceptions.NoReverseMatch: Reverse for 'customer_list' not found. 'customer_list' is not a valid view function or pattern name.
"GET /delete_customer/1/ HTTP/1.1" 500 145
Internal Server Error: /editinvoice/368/
Traceback (most recent call last):
  File "C:\New folder\Lickees\venv\Lib\site-packages\django\core\handlers\exception.py", line 55, in inner
    response = get_response(request)
  File "C:\New folder\Lickees\venv\Lib\site-packages\django\core\handlers\base.py", line 197, in _get_response
    response = wrapped_callback(request, *callback_args, **callback_kwargs)
  File "C:\New folder\Lickees\BillingSoftware\app\views.py", line 634, in edit_invoice
    'invoice_json': json.dumps(invoice_data),
                    ~~~~~~~~~~^^^^^^^^^^^^^^
  File "C:\Users\Nanma-Janaseva\AppData\Local\Programs\Python\Python313\Lib\json\__init__.py", line 231, in dumps
    return _default_encoder.encode(obj)
           ~~~~~~~~~~~~~~~~~~~~~~~^^^^^
  File "C:\Users\Nanma-Janaseva\AppData\Local\Programs\Python\Python313\Lib\json\encoder.py", line 200, in encode
    chunks = self.iterencode(o, _one_shot=True)
  File "C:\Users\Nanma-Janaseva\AppData\Local\Programs\Python\Python313\Lib\json\encoder.py", line 261, in iterencode
    return _iterencode(o, 0)
  File "C:\Users\Nanma-Janaseva\AppData\Local\Programs\Python\Python313\Lib\json\encoder.py", line 180, in default
    raise TypeError(f'Object of type {o.__class__.__name__} '
                    f'is not JSON serializable')
TypeError: Object of type Customer is not JSON serializable
"GET /editinvoice/368/ HTTP/1.1" 500 145
Internal Server Error: /editinvoice/368/
Traceback (most recent call last):
  File "C:\New folder\Lickees\venv\Lib\site-packages\django\core\handlers\exception.py", line 55, in inner
    response = get_response(request)
  File "C:\New folder\Lickees\venv\Lib\site-packages\django\core\handlers\base.py", line 197, in _get_response
    response = wrapped_callback(request, *callback_args, **callback_kwargs)
  File "C:\New folder\Lickees\BillingSoftware\app\views.py", line 497, in edit_invoice
    locations = Location.objects.all()  # Fetch locations, not customers
                ^^^^^^^^
NameError: name 'Location' is not defined
"GET /editinvoice/368/ HTTP/1.1" 500 145
Internal Server Error: /editinvoice/368/
Traceback (most recent call last):
  File "C:\New folder\Lickees\venv\Lib\site-packages\django\core\handlers\exception.py", line 55, in inner
    response = get_response(request)
  File "C:\New folder\Lickees\venv\Lib\site-packages\django\core\handlers\base.py", line 197, in _get_response
    response = wrapped_callback(request, *callback_args, **callback_kwargs)
  File "C:\New folder\Lickees\BillingSoftware\app\views.py", line 497, in edit_invoice
    locations = Location.objects.all()  # Fetch locations, not customers
                ^^^^^^^^
NameError: name 'Location' is not defined
"GET /editinvoice/368/ HTTP/1.1" 500 145
Internal Server Error: /editinvoice/368/
Traceback (most recent call last):
  File "C:\New folder\Lickees\venv\Lib\site-packages\django\core\handlers\exception.py", line 55, in inner
    response = get_response(request)
  File "C:\New folder\Lickees\venv\Lib\site-packages\django\core\handlers\base.py", line 197, in _get_response
    response = wrapped_callback(request, *callback_args, **callback_kwargs)
  File "C:\New folder\Lickees\BillingSoftware\app\views.py", line 497, in edit_invoice
    locations = Location.objects.all()  # Fetch locations, not customers
                ^^^^^^^^
NameError: name 'Location' is not defined
"GET /editinvoice/368/ HTTP/1.1" 500 145
Internal Server Error: /editinvoice/368/
Traceback (most recent call last):
  File "C:\New folder\Lickees\venv\Lib\site-packages\django\core\handlers\exception.py", line 55, in inner
    response = get_response(request)
  File "C:\New folder\Lickees\venv\Lib\site-packages\django\core\handlers\base.py", line 197, in _get_response
    response = wrapped_callback(request, *callback_args, **callback_kwargs)
  File "C:\New folder\Lickees\BillingSoftware\app\views.py", line 497, in edit_invoice
    locations = Customer.objects.all()  # Fetch locations, not customers
                ^
NameError: name 'C' is not defined
"GET /editinvoice/368/ HTTP/1.1" 500 145
Internal Server Error: /editinvoice/368/
Traceback (most recent call last):
  File "C:\New folder\Lickees\venv\Lib\site-packages\django\core\handlers\exception.py", line 55, in inner
    response = get_response(request)
  File "C:\New folder\Lickees\venv\Lib\site-packages\django\core\handlers\base.py", line 197, in _get_response
    response = wrapped_callback(request, *callback_args, **callback_kwargs)
  File "C:\New folder\Lickees\BillingSoftware\app\views.py", line 497, in edit_invoice
    locations = Customer.objects.all()  # Fetch locations, not customers
                ^
NameError: name 'C' is not defined
"GET /editinvoice/368/ HTTP/1.1" 500 145
Internal Server Error: /editinvoice/368/
Traceback (most recent call last):
  File "C:\New folder\Lickees\venv\Lib\site-packages\django\core\handlers\exception.py", line 55, in inner
    response = get_response(request)
  File "C:\New folder\Lickees\venv\Lib\site-packages\django\core\handlers\base.py", line 197, in _get_response
    response = wrapped_callback(request, *callback_args, **callback_kwargs)
  File "C:\New folder\Lickees\BillingSoftware\app\views.py", line 497, in edit_invoice
    locations = Customer.objects.all()  # Fetch locations, not customers
                ^
NameError: name 'C' is not defined
"GET /editinvoice/368/ HTTP/1.1" 500 145
