Internal Server Error: /viewcustomer2/
Traceback (most recent call last):
  File "C:\New folder\Lickees\venv\Lib\site-packages\django\core\handlers\exception.py", line 55, in inner
    response = get_response(request)
  File "C:\New folder\Lickees\venv\Lib\site-packages\django\core\handlers\base.py", line 197, in _get_response
    response = wrapped_callback(request, *callback_args, **callback_kwargs)
  File "C:\New folder\Lickees\BillingSoftware\app2\views.py", line 628, in customer2_list
    return render(request, 'customer_list.html',{'customers': customers})
  File "C:\New folder\Lickees\venv\Lib\site-packages\django\shortcuts.py", line 25, in render
    content = loader.render_to_string(template_name, context, request, using=using)
  File "C:\New folder\Lickees\venv\Lib\site-packages\django\template\loader.py", line 62, in render_to_string
    return template.render(context, request)
           ~~~~~~~~~~~~~~~^^^^^^^^^^^^^^^^^^
  File "C:\New folder\Lickees\venv\Lib\site-packages\django\template\backends\django.py", line 107, in render
    return self.template.render(context)
           ~~~~~~~~~~~~~~~~~~~~^^^^^^^^^
  File "C:\New folder\Lickees\venv\Lib\site-packages\django\template\base.py", line 171, in render
    return self._render(context)
           ~~~~~~~~~~~~^^^^^^^^^
  File "C:\New folder\Lickees\venv\Lib\site-packages\django\template\base.py", line 163, in _render
    return self.nodelist.render(context)
           ~~~~~~~~~~~~~~~~~~~~^^^^^^^^^
  File "C:\New folder\Lickees\venv\Lib\site-packages\django\template\base.py", line 1008, in render
    return SafeString("".join([node.render_annotated(context) for node in self]))
                               ~~~~~~~~~~~~~~~~~~~~~^^^^^^^^^
  File "C:\New folder\Lickees\venv\Lib\site-packages\django\template\base.py", line 969, in render_annotated
    return self.render(context)
           ~~~~~~~~~~~^^^^^^^^^
  File "C:\New folder\Lickees\venv\Lib\site-packages\django\template\defaulttags.py", line 480, in render
    url = reverse(view_name, args=args, kwargs=kwargs, current_app=current_app)
  File "C:\New folder\Lickees\venv\Lib\site-packages\django\urls\base.py", line 88, in reverse
    return resolver._reverse_with_prefix(view, prefix, *args, **kwargs)
           ~~~~~~~~~~~~~~~~~~~~~~~~~~~~~^^^^^^^^^^^^^^^^^^^^^^^^^^^^^^^
  File "C:\New folder\Lickees\venv\Lib\site-packages\django\urls\resolvers.py", line 831, in _reverse_with_prefix
    raise NoReverseMatch(msg)
django.urls.exceptions.NoReverseMatch: Reverse for 'add_customer' not found. 'add_customer' is not a valid view function or pattern name.
"GET /viewcustomer2/ HTTP/1.1" 500 145
Internal Server Error: /viewcustomer2/
Traceback (most recent call last):
  File "C:\New folder\Lickees\venv\Lib\site-packages\django\core\handlers\exception.py", line 55, in inner
    response = get_response(request)
  File "C:\New folder\Lickees\venv\Lib\site-packages\django\core\handlers\base.py", line 197, in _get_response
    response = wrapped_callback(request, *callback_args, **callback_kwargs)
  File "C:\New folder\Lickees\BillingSoftware\app2\views.py", line 628, in customer2_list
    return render(request, 'customer_list.html',{'customers': customers})
  File "C:\New folder\Lickees\venv\Lib\site-packages\django\shortcuts.py", line 25, in render
    content = loader.render_to_string(template_name, context, request, using=using)
  File "C:\New folder\Lickees\venv\Lib\site-packages\django\template\loader.py", line 62, in render_to_string
    return template.render(context, request)
           ~~~~~~~~~~~~~~~^^^^^^^^^^^^^^^^^^
  File "C:\New folder\Lickees\venv\Lib\site-packages\django\template\backends\django.py", line 107, in render
    return self.template.render(context)
           ~~~~~~~~~~~~~~~~~~~~^^^^^^^^^
  File "C:\New folder\Lickees\venv\Lib\site-packages\django\template\base.py", line 171, in render
    return self._render(context)
           ~~~~~~~~~~~~^^^^^^^^^
  File "C:\New folder\Lickees\venv\Lib\site-packages\django\template\base.py", line 163, in _render
    return self.nodelist.render(context)
           ~~~~~~~~~~~~~~~~~~~~^^^^^^^^^
  File "C:\New folder\Lickees\venv\Lib\site-packages\django\template\base.py", line 1008, in render
    return SafeString("".join([node.render_annotated(context) for node in self]))
                               ~~~~~~~~~~~~~~~~~~~~~^^^^^^^^^
  File "C:\New folder\Lickees\venv\Lib\site-packages\django\template\base.py", line 969, in render_annotated
    return self.render(context)
           ~~~~~~~~~~~^^^^^^^^^
  File "C:\New folder\Lickees\venv\Lib\site-packages\django\template\defaulttags.py", line 480, in render
    url = reverse(view_name, args=args, kwargs=kwargs, current_app=current_app)
  File "C:\New folder\Lickees\venv\Lib\site-packages\django\urls\base.py", line 88, in reverse
    return resolver._reverse_with_prefix(view, prefix, *args, **kwargs)
           ~~~~~~~~~~~~~~~~~~~~~~~~~~~~~^^^^^^^^^^^^^^^^^^^^^^^^^^^^^^^
  File "C:\New folder\Lickees\venv\Lib\site-packages\django\urls\resolvers.py", line 831, in _reverse_with_prefix
    raise NoReverseMatch(msg)
django.urls.exceptions.NoReverseMatch: Reverse for 'add_customer' not found. 'add_customer' is not a valid view function or pattern name.
"GET /viewcustomer2/ HTTP/1.1" 500 145
Internal Server Error: /addcustomer2/
Traceback (most recent call last):
  File "C:\New folder\Lickees\venv\Lib\site-packages\django\core\handlers\exception.py", line 55, in inner
    response = get_response(request)
  File "C:\New folder\Lickees\venv\Lib\site-packages\django\core\handlers\base.py", line 197, in _get_response
    response = wrapped_callback(request, *callback_args, **callback_kwargs)
  File "C:\New folder\Lickees\BillingSoftware\app2\views.py", line 628, in addcustomer2
    return redirect('customer2_list')
  File "C:\New folder\Lickees\venv\Lib\site-packages\django\shortcuts.py", line 49, in redirect
    return redirect_class(resolve_url(to, *args, **kwargs))
                          ~~~~~~~~~~~^^^^^^^^^^^^^^^^^^^^^
  File "C:\New folder\Lickees\venv\Lib\site-packages\django\shortcuts.py", line 180, in resolve_url
    return reverse(to, args=args, kwargs=kwargs)
  File "C:\New folder\Lickees\venv\Lib\site-packages\django\urls\base.py", line 88, in reverse
    return resolver._reverse_with_prefix(view, prefix, *args, **kwargs)
           ~~~~~~~~~~~~~~~~~~~~~~~~~~~~~^^^^^^^^^^^^^^^^^^^^^^^^^^^^^^^
  File "C:\New folder\Lickees\venv\Lib\site-packages\django\urls\resolvers.py", line 831, in _reverse_with_prefix
    raise NoReverseMatch(msg)
django.urls.exceptions.NoReverseMatch: Reverse for 'customer2_list' not found. 'customer2_list' is not a valid view function or pattern name.
"POST /addcustomer2/ HTTP/1.1" 500 145
Internal Server Error: /customer_sales_report
Traceback (most recent call last):
  File "C:\New folder\Lickees\venv\Lib\site-packages\django\contrib\sessions\backends\base.py", line 244, in _get_session
    return self._session_cache
           ^^^^^^^^^^^^^^^^^^^
AttributeError: 'SessionStore' object has no attribute '_session_cache'

During handling of the above exception, another exception occurred:

Traceback (most recent call last):
  File "C:\New folder\Lickees\venv\Lib\site-packages\django\db\backends\base\base.py", line 279, in ensure_connection
    self.connect()
    ~~~~~~~~~~~~^^
  File "C:\New folder\Lickees\venv\Lib\site-packages\django\utils\asyncio.py", line 26, in inner
    return func(*args, **kwargs)
  File "C:\New folder\Lickees\venv\Lib\site-packages\django\db\backends\base\base.py", line 256, in connect
    self.connection = self.get_new_connection(conn_params)
                      ~~~~~~~~~~~~~~~~~~~~~~~^^^^^^^^^^^^^
  File "C:\New folder\Lickees\venv\Lib\site-packages\django\utils\asyncio.py", line 26, in inner
    return func(*args, **kwargs)
  File "C:\New folder\Lickees\venv\Lib\site-packages\django\db\backends\postgresql\base.py", line 332, in get_new_connection
    connection = self.Database.connect(**conn_params)
  File "C:\New folder\Lickees\venv\Lib\site-packages\psycopg2\__init__.py", line 135, in connect
    conn = _connect(dsn, connection_factory=connection_factory, **kwasync)
psycopg2.OperationalError: could not translate host name "dpg-cungd21opnds73d6k41g-a.singapore-postgres.render.com" to address: Name or service not known


The above exception was the direct cause of the following exception:

Traceback (most recent call last):
  File "C:\New folder\Lickees\venv\Lib\site-packages\django\core\handlers\exception.py", line 55, in inner
    response = get_response(request)
  File "C:\New folder\Lickees\venv\Lib\site-packages\django\utils\deprecation.py", line 131, in __call__
    response = self.process_response(request, response)
  File "C:\New folder\Lickees\BillingSoftware\app\middleware.py", line 5, in process_response
    if not request.user.is_authenticated:  # If user is logged out
           ^^^^^^^^^^^^^^^^^^^^^^^^^^^^^
  File "C:\New folder\Lickees\venv\Lib\site-packages\django\utils\functional.py", line 251, in inner
    self._setup()
    ~~~~~~~~~~~^^
  File "C:\New folder\Lickees\venv\Lib\site-packages\django\utils\functional.py", line 404, in _setup
    self._wrapped = self._setupfunc()
                    ~~~~~~~~~~~~~~~^^
  File "C:\New folder\Lickees\venv\Lib\site-packages\django\contrib\auth\middleware.py", line 37, in <lambda>
    request.user = SimpleLazyObject(lambda: get_user(request))
                                            ~~~~~~~~^^^^^^^^^
  File "C:\New folder\Lickees\venv\Lib\site-packages\django\contrib\auth\middleware.py", line 17, in get_user
    request._cached_user = auth.get_user(request)
                           ~~~~~~~~~~~~~^^^^^^^^^
  File "C:\New folder\Lickees\venv\Lib\site-packages\django\contrib\auth\__init__.py", line 209, in get_user
    user_id = _get_user_session_key(request)
  File "C:\New folder\Lickees\venv\Lib\site-packages\django\contrib\auth\__init__.py", line 62, in _get_user_session_key
    return get_user_model()._meta.pk.to_python(request.session[SESSION_KEY])
                                               ~~~~~~~~~~~~~~~^^^^^^^^^^^^^
  File "C:\New folder\Lickees\venv\Lib\site-packages\django\contrib\sessions\backends\base.py", line 55, in __getitem__
    return self._session[key]
           ^^^^^^^^^^^^^
  File "C:\New folder\Lickees\venv\Lib\site-packages\django\contrib\sessions\backends\base.py", line 249, in _get_session
    self._session_cache = self.load()
                          ~~~~~~~~~^^
  File "C:\New folder\Lickees\venv\Lib\site-packages\django\contrib\sessions\backends\db.py", line 55, in load
    s = self._get_session_from_db()
  File "C:\New folder\Lickees\venv\Lib\site-packages\django\contrib\sessions\backends\db.py", line 34, in _get_session_from_db
    return self.model.objects.get(
           ~~~~~~~~~~~~~~~~~~~~~~^
        session_key=self.session_key, expire_date__gt=timezone.now()
        ^^^^^^^^^^^^^^^^^^^^^^^^^^^^^^^^^^^^^^^^^^^^^^^^^^^^^^^^^^^^
    )
    ^
  File "C:\New folder\Lickees\venv\Lib\site-packages\django\db\models\manager.py", line 87, in manager_method
    return getattr(self.get_queryset(), name)(*args, **kwargs)
           ~~~~~~~~~~~~~~~~~~~~~~~~~~~~~~~~~~^^^^^^^^^^^^^^^^^
  File "C:\New folder\Lickees\venv\Lib\site-packages\django\db\models\query.py", line 645, in get
    num = len(clone)
  File "C:\New folder\Lickees\venv\Lib\site-packages\django\db\models\query.py", line 382, in __len__
    self._fetch_all()
    ~~~~~~~~~~~~~~~^^
  File "C:\New folder\Lickees\venv\Lib\site-packages\django\db\models\query.py", line 1928, in _fetch_all
    self._result_cache = list(self._iterable_class(self))
                         ~~~~^^^^^^^^^^^^^^^^^^^^^^^^^^^^
  File "C:\New folder\Lickees\venv\Lib\site-packages\django\db\models\query.py", line 91, in __iter__
    results = compiler.execute_sql(
        chunked_fetch=self.chunked_fetch, chunk_size=self.chunk_size
    )
  File "C:\New folder\Lickees\venv\Lib\site-packages\django\db\models\sql\compiler.py", line 1572, in execute_sql
    cursor = self.connection.cursor()
  File "C:\New folder\Lickees\venv\Lib\site-packages\django\utils\asyncio.py", line 26, in inner
    return func(*args, **kwargs)
  File "C:\New folder\Lickees\venv\Lib\site-packages\django\db\backends\base\base.py", line 320, in cursor
    return self._cursor()
           ~~~~~~~~~~~~^^
  File "C:\New folder\Lickees\venv\Lib\site-packages\django\db\backends\base\base.py", line 296, in _cursor
    self.ensure_connection()
    ~~~~~~~~~~~~~~~~~~~~~~^^
  File "C:\New folder\Lickees\venv\Lib\site-packages\django\utils\asyncio.py", line 26, in inner
    return func(*args, **kwargs)
  File "C:\New folder\Lickees\venv\Lib\site-packages\django\db\backends\base\base.py", line 278, in ensure_connection
    with self.wrap_database_errors:
         ^^^^^^^^^^^^^^^^^^^^^^^^^
  File "C:\New folder\Lickees\venv\Lib\site-packages\django\db\utils.py", line 91, in __exit__
    raise dj_exc_value.with_traceback(traceback) from exc_value
  File "C:\New folder\Lickees\venv\Lib\site-packages\django\db\backends\base\base.py", line 279, in ensure_connection
    self.connect()
    ~~~~~~~~~~~~^^
  File "C:\New folder\Lickees\venv\Lib\site-packages\django\utils\asyncio.py", line 26, in inner
    return func(*args, **kwargs)
  File "C:\New folder\Lickees\venv\Lib\site-packages\django\db\backends\base\base.py", line 256, in connect
    self.connection = self.get_new_connection(conn_params)
                      ~~~~~~~~~~~~~~~~~~~~~~~^^^^^^^^^^^^^
  File "C:\New folder\Lickees\venv\Lib\site-packages\django\utils\asyncio.py", line 26, in inner
    return func(*args, **kwargs)
  File "C:\New folder\Lickees\venv\Lib\site-packages\django\db\backends\postgresql\base.py", line 332, in get_new_connection
    connection = self.Database.connect(**conn_params)
  File "C:\New folder\Lickees\venv\Lib\site-packages\psycopg2\__init__.py", line 135, in connect
    conn = _connect(dsn, connection_factory=connection_factory, **kwasync)
django.db.utils.OperationalError: could not translate host name "dpg-cungd21opnds73d6k41g-a.singapore-postgres.render.com" to address: Name or service not known

"GET /customer_sales_report HTTP/1.1" 500 145
Internal Server Error: /createinvoice2/
Traceback (most recent call last):
  File "C:\New folder\Lickees\venv\Lib\site-packages\django\core\handlers\exception.py", line 55, in inner
    response = get_response(request)
  File "C:\New folder\Lickees\venv\Lib\site-packages\django\core\handlers\base.py", line 197, in _get_response
    response = wrapped_callback(request, *callback_args, **callback_kwargs)
  File "C:\New folder\Lickees\BillingSoftware\app2\views.py", line 233, in createinvoice2
    customers = Customer2.objects.all()
                ^^^^^^^^^
NameError: name 'Customer2' is not defined. Did you mean: 'addcustomer2'?
"GET /createinvoice2/ HTTP/1.1" 500 145
Internal Server Error: /createinvoice2/
Traceback (most recent call last):
  File "C:\New folder\Lickees\venv\Lib\site-packages\django\core\handlers\exception.py", line 55, in inner
    response = get_response(request)
  File "C:\New folder\Lickees\venv\Lib\site-packages\django\core\handlers\base.py", line 197, in _get_response
    response = wrapped_callback(request, *callback_args, **callback_kwargs)
  File "C:\New folder\Lickees\BillingSoftware\app2\views.py", line 231, in createinvoice2
    customers = Customer2.objects.all()
                ^^^^^^^^^
NameError: name 'Customer2' is not defined. Did you mean: 'addcustomer2'?
"GET /createinvoice2/ HTTP/1.1" 500 145
Internal Server Error: /createinvoice2/
Traceback (most recent call last):
  File "C:\New folder\Lickees\venv\Lib\site-packages\django\core\handlers\exception.py", line 55, in inner
    response = get_response(request)
  File "C:\New folder\Lickees\venv\Lib\site-packages\django\core\handlers\base.py", line 197, in _get_response
    response = wrapped_callback(request, *callback_args, **callback_kwargs)
  File "C:\New folder\Lickees\BillingSoftware\app2\views.py", line 231, in createinvoice2
    customers = Customer2.objects.all()
                ^^^^^^^^^
NameError: name 'Customer2' is not defined. Did you mean: 'addcustomer2'?
"GET /createinvoice2/ HTTP/1.1" 500 145
Internal Server Error: /createinvoice2/
Traceback (most recent call last):
  File "C:\New folder\Lickees\venv\Lib\site-packages\django\core\handlers\exception.py", line 55, in inner
    response = get_response(request)
  File "C:\New folder\Lickees\venv\Lib\site-packages\django\core\handlers\base.py", line 197, in _get_response
    response = wrapped_callback(request, *callback_args, **callback_kwargs)
  File "C:\New folder\Lickees\BillingSoftware\app2\views.py", line 226, in createinvoice2
    customers = Customer2.objects.all()
                ^^^^^^^^^
NameError: name 'Customer2' is not defined. Did you mean: 'addcustomer2'?
"GET /createinvoice2/ HTTP/1.1" 500 145
Internal Server Error: /createinvoice2/
Traceback (most recent call last):
  File "C:\New folder\Lickees\venv\Lib\site-packages\django\core\handlers\exception.py", line 55, in inner
    response = get_response(request)
  File "C:\New folder\Lickees\venv\Lib\site-packages\django\core\handlers\base.py", line 197, in _get_response
    response = wrapped_callback(request, *callback_args, **callback_kwargs)
  File "C:\New folder\Lickees\BillingSoftware\app2\views.py", line 226, in createinvoice2
    customers = Customer2.objects.all()
                ^^^^^^^^^
NameError: name 'Customer2' is not defined. Did you mean: 'addcustomer2'?
"GET /createinvoice2/ HTTP/1.1" 500 145
Internal Server Error: /createinvoice2/
Traceback (most recent call last):
  File "C:\New folder\Lickees\venv\Lib\site-packages\django\core\handlers\exception.py", line 55, in inner
    response = get_response(request)
  File "C:\New folder\Lickees\venv\Lib\site-packages\django\core\handlers\base.py", line 197, in _get_response
    response = wrapped_callback(request, *callback_args, **callback_kwargs)
  File "C:\New folder\Lickees\BillingSoftware\app2\views.py", line 223, in createinvoice2
    customers = Customer2.objects.all()
                ^^^^^^^^^
NameError: name 'Customer2' is not defined
"GET /createinvoice2/ HTTP/1.1" 500 145
Internal Server Error: /createinvoice2/
Traceback (most recent call last):
  File "C:\New folder\Lickees\venv\Lib\site-packages\django\core\handlers\exception.py", line 55, in inner
    response = get_response(request)
  File "C:\New folder\Lickees\venv\Lib\site-packages\django\core\handlers\base.py", line 197, in _get_response
    response = wrapped_callback(request, *callback_args, **callback_kwargs)
  File "C:\New folder\Lickees\BillingSoftware\app2\views.py", line 223, in createinvoice2
    customers = Customer2.objects.all()
                ^^^^^^^^^
NameError: name 'Customer2' is not defined
"GET /createinvoice2/ HTTP/1.1" 500 145
Internal Server Error: /createinvoice2/
Traceback (most recent call last):
  File "C:\New folder\Lickees\venv\Lib\site-packages\django\core\handlers\exception.py", line 55, in inner
    response = get_response(request)
  File "C:\New folder\Lickees\venv\Lib\site-packages\django\core\handlers\base.py", line 197, in _get_response
    response = wrapped_callback(request, *callback_args, **callback_kwargs)
  File "C:\New folder\Lickees\BillingSoftware\app2\views.py", line 223, in createinvoice2
    customers = Customer2.objects.all()
                ^^^^^^^^^
NameError: name 'Customer2' is not defined
"GET /createinvoice2/ HTTP/1.1" 500 145
Internal Server Error: /userhome2/
Traceback (most recent call last):
  File "C:\New folder\Lickees\venv\Lib\site-packages\django\core\handlers\exception.py", line 55, in inner
    response = get_response(request)
  File "C:\New folder\Lickees\venv\Lib\site-packages\django\core\handlers\base.py", line 197, in _get_response
    response = wrapped_callback(request, *callback_args, **callback_kwargs)
  File "C:\New folder\Lickees\venv\Lib\site-packages\django\views\decorators\cache.py", line 80, in _view_wrapper
    response = view_func(request, *args, **kwargs)
  File "C:\New folder\Lickees\BillingSoftware\app2\views.py", line 302, in userhome2
    return HttpResponse(template.render(context, request))
                        ~~~~~~~~~~~~~~~^^^^^^^^^^^^^^^^^^
  File "C:\New folder\Lickees\venv\Lib\site-packages\django\template\backends\django.py", line 107, in render
    return self.template.render(context)
           ~~~~~~~~~~~~~~~~~~~~^^^^^^^^^
  File "C:\New folder\Lickees\venv\Lib\site-packages\django\template\base.py", line 171, in render
    return self._render(context)
           ~~~~~~~~~~~~^^^^^^^^^
  File "C:\New folder\Lickees\venv\Lib\site-packages\django\template\base.py", line 163, in _render
    return self.nodelist.render(context)
           ~~~~~~~~~~~~~~~~~~~~^^^^^^^^^
  File "C:\New folder\Lickees\venv\Lib\site-packages\django\template\base.py", line 1008, in render
    return SafeString("".join([node.render_annotated(context) for node in self]))
                               ~~~~~~~~~~~~~~~~~~~~~^^^^^^^^^
  File "C:\New folder\Lickees\venv\Lib\site-packages\django\template\base.py", line 969, in render_annotated
    return self.render(context)
           ~~~~~~~~~~~^^^^^^^^^
  File "C:\New folder\Lickees\venv\Lib\site-packages\django\template\defaulttags.py", line 480, in render
    url = reverse(view_name, args=args, kwargs=kwargs, current_app=current_app)
  File "C:\New folder\Lickees\venv\Lib\site-packages\django\urls\base.py", line 88, in reverse
    return resolver._reverse_with_prefix(view, prefix, *args, **kwargs)
           ~~~~~~~~~~~~~~~~~~~~~~~~~~~~~^^^^^^^^^^^^^^^^^^^^^^^^^^^^^^^
  File "C:\New folder\Lickees\venv\Lib\site-packages\django\urls\resolvers.py", line 831, in _reverse_with_prefix
    raise NoReverseMatch(msg)
django.urls.exceptions.NoReverseMatch: Reverse for 'viewcustomer2' not found. 'viewcustomer2' is not a valid view function or pattern name.
"GET /userhome2/ HTTP/1.1" 500 145
Internal Server Error: /userhome2/
Traceback (most recent call last):
  File "C:\New folder\Lickees\venv\Lib\site-packages\django\core\handlers\exception.py", line 55, in inner
    response = get_response(request)
  File "C:\New folder\Lickees\venv\Lib\site-packages\django\core\handlers\base.py", line 197, in _get_response
    response = wrapped_callback(request, *callback_args, **callback_kwargs)
  File "C:\New folder\Lickees\venv\Lib\site-packages\django\views\decorators\cache.py", line 80, in _view_wrapper
    response = view_func(request, *args, **kwargs)
  File "C:\New folder\Lickees\BillingSoftware\app2\views.py", line 302, in userhome2
    return HttpResponse(template.render(context, request))
                        ~~~~~~~~~~~~~~~^^^^^^^^^^^^^^^^^^
  File "C:\New folder\Lickees\venv\Lib\site-packages\django\template\backends\django.py", line 107, in render
    return self.template.render(context)
           ~~~~~~~~~~~~~~~~~~~~^^^^^^^^^
  File "C:\New folder\Lickees\venv\Lib\site-packages\django\template\base.py", line 171, in render
    return self._render(context)
           ~~~~~~~~~~~~^^^^^^^^^
  File "C:\New folder\Lickees\venv\Lib\site-packages\django\template\base.py", line 163, in _render
    return self.nodelist.render(context)
           ~~~~~~~~~~~~~~~~~~~~^^^^^^^^^
  File "C:\New folder\Lickees\venv\Lib\site-packages\django\template\base.py", line 1008, in render
    return SafeString("".join([node.render_annotated(context) for node in self]))
                               ~~~~~~~~~~~~~~~~~~~~~^^^^^^^^^
  File "C:\New folder\Lickees\venv\Lib\site-packages\django\template\base.py", line 969, in render_annotated
    return self.render(context)
           ~~~~~~~~~~~^^^^^^^^^
  File "C:\New folder\Lickees\venv\Lib\site-packages\django\template\defaulttags.py", line 480, in render
    url = reverse(view_name, args=args, kwargs=kwargs, current_app=current_app)
  File "C:\New folder\Lickees\venv\Lib\site-packages\django\urls\base.py", line 88, in reverse
    return resolver._reverse_with_prefix(view, prefix, *args, **kwargs)
           ~~~~~~~~~~~~~~~~~~~~~~~~~~~~~^^^^^^^^^^^^^^^^^^^^^^^^^^^^^^^
  File "C:\New folder\Lickees\venv\Lib\site-packages\django\urls\resolvers.py", line 831, in _reverse_with_prefix
    raise NoReverseMatch(msg)
django.urls.exceptions.NoReverseMatch: Reverse for 'viewcustomer2' not found. 'viewcustomer2' is not a valid view function or pattern name.
"GET /userhome2/ HTTP/1.1" 500 145
Internal Server Error: /addcustomer2/
Traceback (most recent call last):
  File "C:\New folder\Lickees\venv\Lib\site-packages\django\core\handlers\exception.py", line 55, in inner
    response = get_response(request)
  File "C:\New folder\Lickees\venv\Lib\site-packages\django\core\handlers\base.py", line 197, in _get_response
    response = wrapped_callback(request, *callback_args, **callback_kwargs)
  File "C:\New folder\Lickees\BillingSoftware\app2\views.py", line 618, in addcustomer2
    return redirect('customer2_list')
  File "C:\New folder\Lickees\venv\Lib\site-packages\django\shortcuts.py", line 49, in redirect
    return redirect_class(resolve_url(to, *args, **kwargs))
                          ~~~~~~~~~~~^^^^^^^^^^^^^^^^^^^^^
  File "C:\New folder\Lickees\venv\Lib\site-packages\django\shortcuts.py", line 180, in resolve_url
    return reverse(to, args=args, kwargs=kwargs)
  File "C:\New folder\Lickees\venv\Lib\site-packages\django\urls\base.py", line 88, in reverse
    return resolver._reverse_with_prefix(view, prefix, *args, **kwargs)
           ~~~~~~~~~~~~~~~~~~~~~~~~~~~~~^^^^^^^^^^^^^^^^^^^^^^^^^^^^^^^
  File "C:\New folder\Lickees\venv\Lib\site-packages\django\urls\resolvers.py", line 831, in _reverse_with_prefix
    raise NoReverseMatch(msg)
django.urls.exceptions.NoReverseMatch: Reverse for 'customer2_list' not found. 'customer2_list' is not a valid view function or pattern name.
"POST /addcustomer2/ HTTP/1.1" 500 145
Internal Server Error: /createinvoice2/
Traceback (most recent call last):
  File "C:\New folder\Lickees\venv\Lib\site-packages\django\template\smartif.py", line 180, in translate_token
    op = OPERATORS[token]
         ~~~~~~~~~^^^^^^^
KeyError: 'invoice.location.id==c.id'

During handling of the above exception, another exception occurred:

Traceback (most recent call last):
  File "C:\New folder\Lickees\venv\Lib\site-packages\django\core\handlers\exception.py", line 55, in inner
    response = get_response(request)
  File "C:\New folder\Lickees\venv\Lib\site-packages\django\core\handlers\base.py", line 197, in _get_response
    response = wrapped_callback(request, *callback_args, **callback_kwargs)
  File "C:\New folder\Lickees\BillingSoftware\app2\views.py", line 223, in createinvoice2
    return render(request, 'create invoice2.html', {
        'invoice_form': invoice_form,
        'products': products,
    })
  File "C:\New folder\Lickees\venv\Lib\site-packages\django\shortcuts.py", line 25, in render
    content = loader.render_to_string(template_name, context, request, using=using)
  File "C:\New folder\Lickees\venv\Lib\site-packages\django\template\loader.py", line 61, in render_to_string
    template = get_template(template_name, using=using)
  File "C:\New folder\Lickees\venv\Lib\site-packages\django\template\loader.py", line 15, in get_template
    return engine.get_template(template_name)
           ~~~~~~~~~~~~~~~~~~~^^^^^^^^^^^^^^^
  File "C:\New folder\Lickees\venv\Lib\site-packages\django\template\backends\django.py", line 79, in get_template
    return Template(self.engine.get_template(template_name), self)
                    ~~~~~~~~~~~~~~~~~~~~~~~~^^^^^^^^^^^^^^^
  File "C:\New folder\Lickees\venv\Lib\site-packages\django\template\engine.py", line 177, in get_template
    template, origin = self.find_template(template_name)
                       ~~~~~~~~~~~~~~~~~~^^^^^^^^^^^^^^^
  File "C:\New folder\Lickees\venv\Lib\site-packages\django\template\engine.py", line 159, in find_template
    template = loader.get_template(name, skip=skip)
  File "C:\New folder\Lickees\venv\Lib\site-packages\django\template\loaders\cached.py", line 57, in get_template
    template = super().get_template(template_name, skip)
  File "C:\New folder\Lickees\venv\Lib\site-packages\django\template\loaders\base.py", line 28, in get_template
    return Template(
        contents,
    ...<2 lines>...
        self.engine,
    )
  File "C:\New folder\Lickees\venv\Lib\site-packages\django\template\base.py", line 154, in __init__
    self.nodelist = self.compile_nodelist()
                    ~~~~~~~~~~~~~~~~~~~~~^^
  File "C:\New folder\Lickees\venv\Lib\site-packages\django\template\base.py", line 196, in compile_nodelist
    nodelist = parser.parse()
  File "C:\New folder\Lickees\venv\Lib\site-packages\django\template\base.py", line 518, in parse
    raise self.error(token, e)
  File "C:\New folder\Lickees\venv\Lib\site-packages\django\template\base.py", line 516, in parse
    compiled_result = compile_func(self, token)
  File "C:\New folder\Lickees\venv\Lib\site-packages\django\template\defaulttags.py", line 862, in do_for
    nodelist_loop = parser.parse(
        (
    ...<2 lines>...
        )
    )
  File "C:\New folder\Lickees\venv\Lib\site-packages\django\template\base.py", line 518, in parse
    raise self.error(token, e)
  File "C:\New folder\Lickees\venv\Lib\site-packages\django\template\base.py", line 516, in parse
    compiled_result = compile_func(self, token)
  File "C:\New folder\Lickees\venv\Lib\site-packages\django\template\defaulttags.py", line 961, in do_if
    condition = TemplateIfParser(parser, bits).parse()
                ~~~~~~~~~~~~~~~~^^^^^^^^^^^^^^
  File "C:\New folder\Lickees\venv\Lib\site-packages\django\template\defaulttags.py", line 894, in __init__
    super().__init__(*args, **kwargs)
    ~~~~~~~~~~~~~~~~^^^^^^^^^^^^^^^^^
  File "C:\New folder\Lickees\venv\Lib\site-packages\django\template\smartif.py", line 171, in __init__
    mapped_tokens.append(self.translate_token(token))
                         ~~~~~~~~~~~~~~~~~~~~^^^^^^^
  File "C:\New folder\Lickees\venv\Lib\site-packages\django\template\smartif.py", line 182, in translate_token
    return self.create_var(token)
           ~~~~~~~~~~~~~~~^^^^^^^
  File "C:\New folder\Lickees\venv\Lib\site-packages\django\template\defaulttags.py", line 897, in create_var
    return TemplateLiteral(self.template_parser.compile_filter(value), value)
                           ~~~~~~~~~~~~~~~~~~~~~~~~~~~~~~~~~~~^^^^^^^
  File "C:\New folder\Lickees\venv\Lib\site-packages\django\template\base.py", line 605, in compile_filter
    return FilterExpression(token, self)
  File "C:\New folder\Lickees\venv\Lib\site-packages\django\template\base.py", line 706, in __init__
    raise TemplateSyntaxError(
    ...<2 lines>...
    )
django.template.exceptions.TemplateSyntaxError: Could not parse the remainder: '==c.id' from 'invoice.location.id==c.id'
"GET /createinvoice2/ HTTP/1.1" 500 145
Internal Server Error: /createinvoice2/
Traceback (most recent call last):
  File "C:\New folder\Lickees\venv\Lib\site-packages\django\template\base.py", line 510, in parse
    compile_func = self.tags[command]
                   ~~~~~~~~~^^^^^^^^^
KeyError: 'ifequal'

During handling of the above exception, another exception occurred:

Traceback (most recent call last):
  File "C:\New folder\Lickees\venv\Lib\site-packages\django\core\handlers\exception.py", line 55, in inner
    response = get_response(request)
  File "C:\New folder\Lickees\venv\Lib\site-packages\django\core\handlers\base.py", line 197, in _get_response
    response = wrapped_callback(request, *callback_args, **callback_kwargs)
  File "C:\New folder\Lickees\BillingSoftware\app2\views.py", line 223, in createinvoice2
    return render(request, 'create invoice2.html', {
        'invoice_form': invoice_form,
        'products': products,
    })
  File "C:\New folder\Lickees\venv\Lib\site-packages\django\shortcuts.py", line 25, in render
    content = loader.render_to_string(template_name, context, request, using=using)
  File "C:\New folder\Lickees\venv\Lib\site-packages\django\template\loader.py", line 61, in render_to_string
    template = get_template(template_name, using=using)
  File "C:\New folder\Lickees\venv\Lib\site-packages\django\template\loader.py", line 15, in get_template
    return engine.get_template(template_name)
           ~~~~~~~~~~~~~~~~~~~^^^^^^^^^^^^^^^
  File "C:\New folder\Lickees\venv\Lib\site-packages\django\template\backends\django.py", line 79, in get_template
    return Template(self.engine.get_template(template_name), self)
                    ~~~~~~~~~~~~~~~~~~~~~~~~^^^^^^^^^^^^^^^
  File "C:\New folder\Lickees\venv\Lib\site-packages\django\template\engine.py", line 177, in get_template
    template, origin = self.find_template(template_name)
                       ~~~~~~~~~~~~~~~~~~^^^^^^^^^^^^^^^
  File "C:\New folder\Lickees\venv\Lib\site-packages\django\template\engine.py", line 159, in find_template
    template = loader.get_template(name, skip=skip)
  File "C:\New folder\Lickees\venv\Lib\site-packages\django\template\loaders\cached.py", line 57, in get_template
    template = super().get_template(template_name, skip)
  File "C:\New folder\Lickees\venv\Lib\site-packages\django\template\loaders\base.py", line 28, in get_template
    return Template(
        contents,
    ...<2 lines>...
        self.engine,
    )
  File "C:\New folder\Lickees\venv\Lib\site-packages\django\template\base.py", line 154, in __init__
    self.nodelist = self.compile_nodelist()
                    ~~~~~~~~~~~~~~~~~~~~~^^
  File "C:\New folder\Lickees\venv\Lib\site-packages\django\template\base.py", line 196, in compile_nodelist
    nodelist = parser.parse()
  File "C:\New folder\Lickees\venv\Lib\site-packages\django\template\base.py", line 518, in parse
    raise self.error(token, e)
  File "C:\New folder\Lickees\venv\Lib\site-packages\django\template\base.py", line 516, in parse
    compiled_result = compile_func(self, token)
  File "C:\New folder\Lickees\venv\Lib\site-packages\django\template\defaulttags.py", line 862, in do_for
    nodelist_loop = parser.parse(
        (
    ...<2 lines>...
        )
    )
  File "C:\New folder\Lickees\venv\Lib\site-packages\django\template\base.py", line 512, in parse
    self.invalid_block_tag(token, command, parse_until)
    ~~~~~~~~~~~~~~~~~~~~~~^^^^^^^^^^^^^^^^^^^^^^^^^^^^^
  File "C:\New folder\Lickees\venv\Lib\site-packages\django\template\base.py", line 563, in invalid_block_tag
    raise self.error(
    ...<8 lines>...
    )
django.template.exceptions.TemplateSyntaxError: Invalid block tag on line 322: 'ifequal', expected 'empty' or 'endfor'. Did you forget to register or load this tag?
"GET /createinvoice2/ HTTP/1.1" 500 145
Internal Server Error: /createinvoice2/
Traceback (most recent call last):
  File "C:\New folder\Lickees\venv\Lib\site-packages\django\template\base.py", line 510, in parse
    compile_func = self.tags[command]
                   ~~~~~~~~~^^^^^^^^^
KeyError: 'ifequal'

During handling of the above exception, another exception occurred:

Traceback (most recent call last):
  File "C:\New folder\Lickees\venv\Lib\site-packages\django\core\handlers\exception.py", line 55, in inner
    response = get_response(request)
  File "C:\New folder\Lickees\venv\Lib\site-packages\django\core\handlers\base.py", line 197, in _get_response
    response = wrapped_callback(request, *callback_args, **callback_kwargs)
  File "C:\New folder\Lickees\BillingSoftware\app2\views.py", line 223, in createinvoice2
    return render(request, 'create invoice2.html', {
        'invoice_form': invoice_form,
        'products': products,
    })
  File "C:\New folder\Lickees\venv\Lib\site-packages\django\shortcuts.py", line 25, in render
    content = loader.render_to_string(template_name, context, request, using=using)
  File "C:\New folder\Lickees\venv\Lib\site-packages\django\template\loader.py", line 61, in render_to_string
    template = get_template(template_name, using=using)
  File "C:\New folder\Lickees\venv\Lib\site-packages\django\template\loader.py", line 15, in get_template
    return engine.get_template(template_name)
           ~~~~~~~~~~~~~~~~~~~^^^^^^^^^^^^^^^
  File "C:\New folder\Lickees\venv\Lib\site-packages\django\template\backends\django.py", line 79, in get_template
    return Template(self.engine.get_template(template_name), self)
                    ~~~~~~~~~~~~~~~~~~~~~~~~^^^^^^^^^^^^^^^
  File "C:\New folder\Lickees\venv\Lib\site-packages\django\template\engine.py", line 177, in get_template
    template, origin = self.find_template(template_name)
                       ~~~~~~~~~~~~~~~~~~^^^^^^^^^^^^^^^
  File "C:\New folder\Lickees\venv\Lib\site-packages\django\template\engine.py", line 159, in find_template
    template = loader.get_template(name, skip=skip)
  File "C:\New folder\Lickees\venv\Lib\site-packages\django\template\loaders\cached.py", line 57, in get_template
    template = super().get_template(template_name, skip)
  File "C:\New folder\Lickees\venv\Lib\site-packages\django\template\loaders\base.py", line 28, in get_template
    return Template(
        contents,
    ...<2 lines>...
        self.engine,
    )
  File "C:\New folder\Lickees\venv\Lib\site-packages\django\template\base.py", line 154, in __init__
    self.nodelist = self.compile_nodelist()
                    ~~~~~~~~~~~~~~~~~~~~~^^
  File "C:\New folder\Lickees\venv\Lib\site-packages\django\template\base.py", line 196, in compile_nodelist
    nodelist = parser.parse()
  File "C:\New folder\Lickees\venv\Lib\site-packages\django\template\base.py", line 518, in parse
    raise self.error(token, e)
  File "C:\New folder\Lickees\venv\Lib\site-packages\django\template\base.py", line 516, in parse
    compiled_result = compile_func(self, token)
  File "C:\New folder\Lickees\venv\Lib\site-packages\django\template\defaulttags.py", line 862, in do_for
    nodelist_loop = parser.parse(
        (
    ...<2 lines>...
        )
    )
  File "C:\New folder\Lickees\venv\Lib\site-packages\django\template\base.py", line 512, in parse
    self.invalid_block_tag(token, command, parse_until)
    ~~~~~~~~~~~~~~~~~~~~~~^^^^^^^^^^^^^^^^^^^^^^^^^^^^^
  File "C:\New folder\Lickees\venv\Lib\site-packages\django\template\base.py", line 563, in invalid_block_tag
    raise self.error(
    ...<8 lines>...
    )
django.template.exceptions.TemplateSyntaxError: Invalid block tag on line 322: 'ifequal', expected 'empty' or 'endfor'. Did you forget to register or load this tag?
"GET /createinvoice2/ HTTP/1.1" 500 145
Internal Server Error: /createinvoice2/
Traceback (most recent call last):
  File "C:\New folder\Lickees\venv\Lib\site-packages\django\template\base.py", line 510, in parse
    compile_func = self.tags[command]
                   ~~~~~~~~~^^^^^^^^^
KeyError: 'ifequal'

During handling of the above exception, another exception occurred:

Traceback (most recent call last):
  File "C:\New folder\Lickees\venv\Lib\site-packages\django\core\handlers\exception.py", line 55, in inner
    response = get_response(request)
  File "C:\New folder\Lickees\venv\Lib\site-packages\django\core\handlers\base.py", line 197, in _get_response
    response = wrapped_callback(request, *callback_args, **callback_kwargs)
  File "C:\New folder\Lickees\BillingSoftware\app2\views.py", line 223, in createinvoice2
    return render(request, 'create invoice2.html', {
        'invoice_form': invoice_form,
        'products': products,
    })
  File "C:\New folder\Lickees\venv\Lib\site-packages\django\shortcuts.py", line 25, in render
    content = loader.render_to_string(template_name, context, request, using=using)
  File "C:\New folder\Lickees\venv\Lib\site-packages\django\template\loader.py", line 61, in render_to_string
    template = get_template(template_name, using=using)
  File "C:\New folder\Lickees\venv\Lib\site-packages\django\template\loader.py", line 15, in get_template
    return engine.get_template(template_name)
           ~~~~~~~~~~~~~~~~~~~^^^^^^^^^^^^^^^
  File "C:\New folder\Lickees\venv\Lib\site-packages\django\template\backends\django.py", line 79, in get_template
    return Template(self.engine.get_template(template_name), self)
                    ~~~~~~~~~~~~~~~~~~~~~~~~^^^^^^^^^^^^^^^
  File "C:\New folder\Lickees\venv\Lib\site-packages\django\template\engine.py", line 177, in get_template
    template, origin = self.find_template(template_name)
                       ~~~~~~~~~~~~~~~~~~^^^^^^^^^^^^^^^
  File "C:\New folder\Lickees\venv\Lib\site-packages\django\template\engine.py", line 159, in find_template
    template = loader.get_template(name, skip=skip)
  File "C:\New folder\Lickees\venv\Lib\site-packages\django\template\loaders\cached.py", line 57, in get_template
    template = super().get_template(template_name, skip)
  File "C:\New folder\Lickees\venv\Lib\site-packages\django\template\loaders\base.py", line 28, in get_template
    return Template(
        contents,
    ...<2 lines>...
        self.engine,
    )
  File "C:\New folder\Lickees\venv\Lib\site-packages\django\template\base.py", line 154, in __init__
    self.nodelist = self.compile_nodelist()
                    ~~~~~~~~~~~~~~~~~~~~~^^
  File "C:\New folder\Lickees\venv\Lib\site-packages\django\template\base.py", line 196, in compile_nodelist
    nodelist = parser.parse()
  File "C:\New folder\Lickees\venv\Lib\site-packages\django\template\base.py", line 518, in parse
    raise self.error(token, e)
  File "C:\New folder\Lickees\venv\Lib\site-packages\django\template\base.py", line 516, in parse
    compiled_result = compile_func(self, token)
  File "C:\New folder\Lickees\venv\Lib\site-packages\django\template\defaulttags.py", line 862, in do_for
    nodelist_loop = parser.parse(
        (
    ...<2 lines>...
        )
    )
  File "C:\New folder\Lickees\venv\Lib\site-packages\django\template\base.py", line 512, in parse
    self.invalid_block_tag(token, command, parse_until)
    ~~~~~~~~~~~~~~~~~~~~~~^^^^^^^^^^^^^^^^^^^^^^^^^^^^^
  File "C:\New folder\Lickees\venv\Lib\site-packages\django\template\base.py", line 563, in invalid_block_tag
    raise self.error(
    ...<8 lines>...
    )
django.template.exceptions.TemplateSyntaxError: Invalid block tag on line 322: 'ifequal', expected 'empty' or 'endfor'. Did you forget to register or load this tag?
"GET /createinvoice2/ HTTP/1.1" 500 145
Internal Server Error: /userhome2/
Traceback (most recent call last):
  File "C:\New folder\Lickees\venv\Lib\site-packages\django\core\handlers\exception.py", line 55, in inner
    response = get_response(request)
  File "C:\New folder\Lickees\venv\Lib\site-packages\django\core\handlers\base.py", line 197, in _get_response
    response = wrapped_callback(request, *callback_args, **callback_kwargs)
  File "C:\New folder\Lickees\venv\Lib\site-packages\django\views\decorators\cache.py", line 80, in _view_wrapper
    response = view_func(request, *args, **kwargs)
  File "C:\New folder\Lickees\BillingSoftware\app2\views.py", line 314, in userhome2
    return HttpResponse(template.render(context, request))
                        ~~~~~~~~~~~~~~~^^^^^^^^^^^^^^^^^^
  File "C:\New folder\Lickees\venv\Lib\site-packages\django\template\backends\django.py", line 107, in render
    return self.template.render(context)
           ~~~~~~~~~~~~~~~~~~~~^^^^^^^^^
  File "C:\New folder\Lickees\venv\Lib\site-packages\django\template\base.py", line 171, in render
    return self._render(context)
           ~~~~~~~~~~~~^^^^^^^^^
  File "C:\New folder\Lickees\venv\Lib\site-packages\django\template\base.py", line 163, in _render
    return self.nodelist.render(context)
           ~~~~~~~~~~~~~~~~~~~~^^^^^^^^^
  File "C:\New folder\Lickees\venv\Lib\site-packages\django\template\base.py", line 1008, in render
    return SafeString("".join([node.render_annotated(context) for node in self]))
                               ~~~~~~~~~~~~~~~~~~~~~^^^^^^^^^
  File "C:\New folder\Lickees\venv\Lib\site-packages\django\template\base.py", line 969, in render_annotated
    return self.render(context)
           ~~~~~~~~~~~^^^^^^^^^
  File "C:\New folder\Lickees\venv\Lib\site-packages\django\template\defaulttags.py", line 480, in render
    url = reverse(view_name, args=args, kwargs=kwargs, current_app=current_app)
  File "C:\New folder\Lickees\venv\Lib\site-packages\django\urls\base.py", line 88, in reverse
    return resolver._reverse_with_prefix(view, prefix, *args, **kwargs)
           ~~~~~~~~~~~~~~~~~~~~~~~~~~~~~^^^^^^^^^^^^^^^^^^^^^^^^^^^^^^^
  File "C:\New folder\Lickees\venv\Lib\site-packages\django\urls\resolvers.py", line 831, in _reverse_with_prefix
    raise NoReverseMatch(msg)
django.urls.exceptions.NoReverseMatch: Reverse for 'location_report2' not found. 'location_report2' is not a valid view function or pattern name.
"GET /userhome2/ HTTP/1.1" 500 145
Internal Server Error: /userhome2/
Traceback (most recent call last):
  File "C:\New folder\Lickees\venv\Lib\site-packages\django\core\handlers\exception.py", line 55, in inner
    response = get_response(request)
  File "C:\New folder\Lickees\venv\Lib\site-packages\django\core\handlers\base.py", line 197, in _get_response
    response = wrapped_callback(request, *callback_args, **callback_kwargs)
  File "C:\New folder\Lickees\venv\Lib\site-packages\django\views\decorators\cache.py", line 80, in _view_wrapper
    response = view_func(request, *args, **kwargs)
  File "C:\New folder\Lickees\BillingSoftware\app2\views.py", line 314, in userhome2
    return HttpResponse(template.render(context, request))
                        ~~~~~~~~~~~~~~~^^^^^^^^^^^^^^^^^^
  File "C:\New folder\Lickees\venv\Lib\site-packages\django\template\backends\django.py", line 107, in render
    return self.template.render(context)
           ~~~~~~~~~~~~~~~~~~~~^^^^^^^^^
  File "C:\New folder\Lickees\venv\Lib\site-packages\django\template\base.py", line 171, in render
    return self._render(context)
           ~~~~~~~~~~~~^^^^^^^^^
  File "C:\New folder\Lickees\venv\Lib\site-packages\django\template\base.py", line 163, in _render
    return self.nodelist.render(context)
           ~~~~~~~~~~~~~~~~~~~~^^^^^^^^^
  File "C:\New folder\Lickees\venv\Lib\site-packages\django\template\base.py", line 1008, in render
    return SafeString("".join([node.render_annotated(context) for node in self]))
                               ~~~~~~~~~~~~~~~~~~~~~^^^^^^^^^
  File "C:\New folder\Lickees\venv\Lib\site-packages\django\template\base.py", line 969, in render_annotated
    return self.render(context)
           ~~~~~~~~~~~^^^^^^^^^
  File "C:\New folder\Lickees\venv\Lib\site-packages\django\template\defaulttags.py", line 480, in render
    url = reverse(view_name, args=args, kwargs=kwargs, current_app=current_app)
  File "C:\New folder\Lickees\venv\Lib\site-packages\django\urls\base.py", line 88, in reverse
    return resolver._reverse_with_prefix(view, prefix, *args, **kwargs)
           ~~~~~~~~~~~~~~~~~~~~~~~~~~~~~^^^^^^^^^^^^^^^^^^^^^^^^^^^^^^^
  File "C:\New folder\Lickees\venv\Lib\site-packages\django\urls\resolvers.py", line 831, in _reverse_with_prefix
    raise NoReverseMatch(msg)
django.urls.exceptions.NoReverseMatch: Reverse for 'location_report' not found. 'location_report' is not a valid view function or pattern name.
"GET /userhome2/ HTTP/1.1" 500 145
Internal Server Error: /userhome2/
Traceback (most recent call last):
  File "C:\New folder\Lickees\venv\Lib\site-packages\django\core\handlers\exception.py", line 55, in inner
    response = get_response(request)
  File "C:\New folder\Lickees\venv\Lib\site-packages\django\core\handlers\base.py", line 197, in _get_response
    response = wrapped_callback(request, *callback_args, **callback_kwargs)
  File "C:\New folder\Lickees\venv\Lib\site-packages\django\views\decorators\cache.py", line 80, in _view_wrapper
    response = view_func(request, *args, **kwargs)
  File "C:\New folder\Lickees\BillingSoftware\app2\views.py", line 314, in userhome2
    return HttpResponse(template.render(context, request))
                        ~~~~~~~~~~~~~~~^^^^^^^^^^^^^^^^^^
  File "C:\New folder\Lickees\venv\Lib\site-packages\django\template\backends\django.py", line 107, in render
    return self.template.render(context)
           ~~~~~~~~~~~~~~~~~~~~^^^^^^^^^
  File "C:\New folder\Lickees\venv\Lib\site-packages\django\template\base.py", line 171, in render
    return self._render(context)
           ~~~~~~~~~~~~^^^^^^^^^
  File "C:\New folder\Lickees\venv\Lib\site-packages\django\template\base.py", line 163, in _render
    return self.nodelist.render(context)
           ~~~~~~~~~~~~~~~~~~~~^^^^^^^^^
  File "C:\New folder\Lickees\venv\Lib\site-packages\django\template\base.py", line 1008, in render
    return SafeString("".join([node.render_annotated(context) for node in self]))
                               ~~~~~~~~~~~~~~~~~~~~~^^^^^^^^^
  File "C:\New folder\Lickees\venv\Lib\site-packages\django\template\base.py", line 969, in render_annotated
    return self.render(context)
           ~~~~~~~~~~~^^^^^^^^^
  File "C:\New folder\Lickees\venv\Lib\site-packages\django\template\defaulttags.py", line 480, in render
    url = reverse(view_name, args=args, kwargs=kwargs, current_app=current_app)
  File "C:\New folder\Lickees\venv\Lib\site-packages\django\urls\base.py", line 88, in reverse
    return resolver._reverse_with_prefix(view, prefix, *args, **kwargs)
           ~~~~~~~~~~~~~~~~~~~~~~~~~~~~~^^^^^^^^^^^^^^^^^^^^^^^^^^^^^^^
  File "C:\New folder\Lickees\venv\Lib\site-packages\django\urls\resolvers.py", line 831, in _reverse_with_prefix
    raise NoReverseMatch(msg)
django.urls.exceptions.NoReverseMatch: Reverse for 'location_report2' not found. 'location_report2' is not a valid view function or pattern name.
"GET /userhome2/ HTTP/1.1" 500 145
Internal Server Error: /userhome2/
Traceback (most recent call last):
  File "C:\New folder\Lickees\venv\Lib\site-packages\django\core\handlers\exception.py", line 55, in inner
    response = get_response(request)
  File "C:\New folder\Lickees\venv\Lib\site-packages\django\core\handlers\base.py", line 197, in _get_response
    response = wrapped_callback(request, *callback_args, **callback_kwargs)
  File "C:\New folder\Lickees\venv\Lib\site-packages\django\views\decorators\cache.py", line 80, in _view_wrapper
    response = view_func(request, *args, **kwargs)
  File "C:\New folder\Lickees\BillingSoftware\app2\views.py", line 314, in userhome2
    return HttpResponse(template.render(context, request))
                        ~~~~~~~~~~~~~~~^^^^^^^^^^^^^^^^^^
  File "C:\New folder\Lickees\venv\Lib\site-packages\django\template\backends\django.py", line 107, in render
    return self.template.render(context)
           ~~~~~~~~~~~~~~~~~~~~^^^^^^^^^
  File "C:\New folder\Lickees\venv\Lib\site-packages\django\template\base.py", line 171, in render
    return self._render(context)
           ~~~~~~~~~~~~^^^^^^^^^
  File "C:\New folder\Lickees\venv\Lib\site-packages\django\template\base.py", line 163, in _render
    return self.nodelist.render(context)
           ~~~~~~~~~~~~~~~~~~~~^^^^^^^^^
  File "C:\New folder\Lickees\venv\Lib\site-packages\django\template\base.py", line 1008, in render
    return SafeString("".join([node.render_annotated(context) for node in self]))
                               ~~~~~~~~~~~~~~~~~~~~~^^^^^^^^^
  File "C:\New folder\Lickees\venv\Lib\site-packages\django\template\base.py", line 969, in render_annotated
    return self.render(context)
           ~~~~~~~~~~~^^^^^^^^^
  File "C:\New folder\Lickees\venv\Lib\site-packages\django\template\defaulttags.py", line 480, in render
    url = reverse(view_name, args=args, kwargs=kwargs, current_app=current_app)
  File "C:\New folder\Lickees\venv\Lib\site-packages\django\urls\base.py", line 88, in reverse
    return resolver._reverse_with_prefix(view, prefix, *args, **kwargs)
           ~~~~~~~~~~~~~~~~~~~~~~~~~~~~~^^^^^^^^^^^^^^^^^^^^^^^^^^^^^^^
  File "C:\New folder\Lickees\venv\Lib\site-packages\django\urls\resolvers.py", line 831, in _reverse_with_prefix
    raise NoReverseMatch(msg)
django.urls.exceptions.NoReverseMatch: Reverse for 'location_report2' not found. 'location_report2' is not a valid view function or pattern name.
"GET /userhome2/ HTTP/1.1" 500 145
Internal Server Error: /userhome2/
Traceback (most recent call last):
  File "C:\New folder\Lickees\venv\Lib\site-packages\django\core\handlers\exception.py", line 55, in inner
    response = get_response(request)
  File "C:\New folder\Lickees\venv\Lib\site-packages\django\core\handlers\base.py", line 197, in _get_response
    response = wrapped_callback(request, *callback_args, **callback_kwargs)
  File "C:\New folder\Lickees\venv\Lib\site-packages\django\views\decorators\cache.py", line 80, in _view_wrapper
    response = view_func(request, *args, **kwargs)
  File "C:\New folder\Lickees\BillingSoftware\app2\views.py", line 314, in userhome2
    return HttpResponse(template.render(context, request))
                        ~~~~~~~~~~~~~~~^^^^^^^^^^^^^^^^^^
  File "C:\New folder\Lickees\venv\Lib\site-packages\django\template\backends\django.py", line 107, in render
    return self.template.render(context)
           ~~~~~~~~~~~~~~~~~~~~^^^^^^^^^
  File "C:\New folder\Lickees\venv\Lib\site-packages\django\template\base.py", line 171, in render
    return self._render(context)
           ~~~~~~~~~~~~^^^^^^^^^
  File "C:\New folder\Lickees\venv\Lib\site-packages\django\template\base.py", line 163, in _render
    return self.nodelist.render(context)
           ~~~~~~~~~~~~~~~~~~~~^^^^^^^^^
  File "C:\New folder\Lickees\venv\Lib\site-packages\django\template\base.py", line 1008, in render
    return SafeString("".join([node.render_annotated(context) for node in self]))
                               ~~~~~~~~~~~~~~~~~~~~~^^^^^^^^^
  File "C:\New folder\Lickees\venv\Lib\site-packages\django\template\base.py", line 969, in render_annotated
    return self.render(context)
           ~~~~~~~~~~~^^^^^^^^^
  File "C:\New folder\Lickees\venv\Lib\site-packages\django\template\defaulttags.py", line 480, in render
    url = reverse(view_name, args=args, kwargs=kwargs, current_app=current_app)
  File "C:\New folder\Lickees\venv\Lib\site-packages\django\urls\base.py", line 88, in reverse
    return resolver._reverse_with_prefix(view, prefix, *args, **kwargs)
           ~~~~~~~~~~~~~~~~~~~~~~~~~~~~~^^^^^^^^^^^^^^^^^^^^^^^^^^^^^^^
  File "C:\New folder\Lickees\venv\Lib\site-packages\django\urls\resolvers.py", line 831, in _reverse_with_prefix
    raise NoReverseMatch(msg)
django.urls.exceptions.NoReverseMatch: Reverse for 'location_report2' not found. 'location_report2' is not a valid view function or pattern name.
"GET /userhome2/ HTTP/1.1" 500 145
